Traceback (most recent call last):
  File "/opt/hostedtoolcache/Python/3.13.5/x64/lib/python3.13/site-packages/jupyter_core/utils/__init__.py", line 154, in wrapped
    asyncio.get_running_loop()
    ~~~~~~~~~~~~~~~~~~~~~~~~^^
RuntimeError: no running event loop

During handling of the above exception, another exception occurred:

Traceback (most recent call last):
  File "/opt/hostedtoolcache/Python/3.13.5/x64/lib/python3.13/site-packages/jupyter_cache/executors/utils.py", line 58, in single_nb_execution
    executenb(
    ~~~~~~~~~^
        nb,
        ^^^
    ...<4 lines>...
        **kwargs,
        ^^^^^^^^^
    )
    ^
  File "/opt/hostedtoolcache/Python/3.13.5/x64/lib/python3.13/site-packages/nbclient/client.py", line 1319, in execute
    return NotebookClient(nb=nb, resources=resources, km=km, **kwargs).execute()
           ~~~~~~~~~~~~~~~~~~~~~~~~~~~~~~~~~~~~~~~~~~~~~~~~~~~~~~~~~~~~~~~~~~~^^
  File "/opt/hostedtoolcache/Python/3.13.5/x64/lib/python3.13/site-packages/jupyter_core/utils/__init__.py", line 158, in wrapped
    return loop.run_until_complete(inner)
           ~~~~~~~~~~~~~~~~~~~~~~~^^^^^^^
  File "/opt/hostedtoolcache/Python/3.13.5/x64/lib/python3.13/asyncio/base_events.py", line 725, in run_until_complete
    return future.result()
           ~~~~~~~~~~~~~^^
  File "/opt/hostedtoolcache/Python/3.13.5/x64/lib/python3.13/site-packages/nbclient/client.py", line 709, in async_execute
    await self.async_execute_cell(
        cell, index, execution_count=self.code_cells_executed + 1
    )
  File "/opt/hostedtoolcache/Python/3.13.5/x64/lib/python3.13/site-packages/nbclient/client.py", line 1062, in async_execute_cell
    await self._check_raise_for_error(cell, cell_index, exec_reply)
  File "/opt/hostedtoolcache/Python/3.13.5/x64/lib/python3.13/site-packages/nbclient/client.py", line 918, in _check_raise_for_error
    raise CellExecutionError.from_cell_and_msg(cell, exec_reply_content)
nbclient.exceptions.CellExecutionError: An error occurred while executing the following cell:
------------------
!printf "\xf0" | fandango parse -f bits.fan -o - --format=bits --validate
assert _exit_code == 0
------------------

----- stdout -----
FandangoParseError: '<stdin>', position 0x0001 (1): mismatched input b'x'
FandangoParseError: 1 error(s) during parsing
------------------

[31m---------------------------------------------------------------------------[39m
[31mAssertionError[39m                            Traceback (most recent call last)
[36mCell[39m[36m [39m[32mIn[6][39m[32m, line 2[39m
[32m      1[39m get_ipython().system([33m'[39m[33mprintf [39m[33m"[39m[38;5;130;01m\\[39;00m[33mxf0[39m[33m"[39m[33m | fandango parse -f bits.fan -o - --format=bits --validate[39m[33m'[39m)
[32m----> [39m[32m2[39m [38;5;28;01massert[39;00m _exit_code == [32m0[39m

[31mAssertionError[39m: 

